Workbook

Sheet 115年總表
C2: 垃圾進廠量 (公噸) | G2: 燃燒量(公噸) | J2: 熱值(仟卡) | L2: 蒸汽量(T/H) | N2: 電力(MWh) | R2: 化學藥品使用量(公斤) | U2: 日常使用量 | Y2: 廢棄物運出(公噸)
B3: 年/月 | C3: 公所 | D3: 轉運 | E3: 事廢 | F3: 本月進廠量 | G3: 一號爐 | H3: 二號爐 | I3: 合計 | J3: 一號爐 | K3: 二號爐 | L3: 一號爐 | M3: 二號爐 | N3: 發電量 | O3: 售電量 | P3: 廠內用電 | Q3: 售電率 | R3: 消石灰 | S3: 活性碳 | T3: 尿素 | U3: 柴油(公升) | V3: 純水(公噸) | W3: 自來水用表(公噸) | X3: 電表 | Y3: 底渣 | Z3: 飛灰
B4: 合計 | C4: =SUM(C5:C28) -> 3245.93 | D4: =SUM(D5:D28) -> 5099.37 | E4: =SUM(E5:E28) -> 761.02 | F4: =SUM(F5:F28) -> 9106.32 | G4: =SUM(G5:G28) -> 3815.9 | H4: =SUM(H5:H28) -> 4119.91 | I4: =SUM(I5:I28) -> 7935.81 | J4: =AVERAGE(J5:J40) -> 329.23086 | K4: =AVERAGE(K5:K40) -> 350.85538 | L4: =AVERAGE(L5:L40) -> 2.4610484 | M4: =AVERAGE(M5:M40) -> 2.8026882 | N4: =SUM(N5:N28) -> 3983.52 | O4: =SUM(O5:O28) -> 3288.96 | P4: =SUM(P5:P28) -> 694.56 | Q4: =IFERROR(O4/N4*100,0) -> 82.564164 | R4: =SUM(R5:R28) -> 88800 | S4: =SUM(S5:S28) -> 1536 | T4: =SUM(T5:T28) -> 11483 | U4: =SUM(U5:U28) -> 210 | V4: =SUM(V5:V28) -> 1554.24 | W4: =SUM(W5:W28) -> 2200 | X4: =SUM(X5:X28) -> 0 | Y4: =SUM(Y5:Y28) -> 388.52 | Z4: =SUM(Z5:Z28) -> 312.08
B5: 115/1 | C5: ='每日填寫-115年數據'!C4 -> 3049.06 | D5: ='每日填寫-115年數據'!D4 -> 4855.29 | E5: ='每日填寫-115年數據'!E4 -> 719.28 | F5: ='每日填寫-115年數據'!F4 -> 8623.63 | G5: ='每日填寫-115年數據'!G4 -> 3690.04 | H5: ='每日填寫-115年數據'!H4 -> 3988.31 | I5: ='每日填寫-115年數據'!I4 -> 7678.35 | J5: ='每日填寫-115年數據'!J4 -> 1940.0003 | ... Z5: ='每日填寫-115年數據'!Z4 -> 312.08
B6: 115/2 | C6: ='每日填寫-115年數據'!C39 -> 196.87 | D6: ='每日填寫-115年數據'!D39 -> 244.08 | E6: ='每日填寫-115年數據'!E39 -> 41.74 | F6: ='每日填寫-115年數據'!F39 -> 482.69 | G6: ='每日填寫-115年數據'!G39 -> 125.86 | H6: ='每日填寫-115年數據'!H39 -> 131.6 | I6: ='每日填寫-115年數據'!I39 -> 257.46 | J6: ='每日填寫-115年數據'!J39 -> 2010.77 | ... Z6: ='每日填寫-115年數據'!Z39 -> 0
B7: 115/3 | C7: ='每日填寫-115年數據'!C71 -> 0 | D7: ='每日填寫-115年數據'!D71 -> 0 | E7: ='每日填寫-115年數據'!E71 -> 0 | F7: ='每日填寫-115年數據'!F71 -> 0 | G7: ='每日填寫-115年數據'!G71 -> 0 | H7: ='每日填寫-115年數據'!H71 -> 0 | I7: ='每日填寫-115年數據'!I71 -> 0 | J7: ='每日填寫-115年數據'!J71 -> 0 | ... Z7: ='每日填寫-115年數據'!Z71 -> 0
B8: 115/4 | C8: ='每日填寫-115年數據'!C106 -> 0 | D8: ='每日填寫-115年數據'!D106 -> 0 | E8: ='每日填寫-115年數據'!E106 -> 0 | F8: ='每日填寫-115年數據'!F106 -> 0 | G8: ='每日填寫-115年數據'!G106 -> 0 | H8: ='每日填寫-115年數據'!H106 -> 0 | I8: ='每日填寫-115年數據'!I106 -> 0 | J8: ='每日填寫-115年數據'!J106 -> 0 | ... Z8: ='每日填寫-115年數據'!Z106 -> 0
B9: 115/5 | C9: ='每日填寫-115年數據'!C140 -> 0 | D9: ='每日填寫-115年數據'!D140 -> 0 | E9: ='每日填寫-115年數據'!E140 -> 0 | F9: ='每日填寫-115年數據'!F140 -> 0 | G9: ='每日填寫-115年數據'!G140 -> 0 | H9: ='每日填寫-115年數據'!H140 -> 0 | I9: ='每日填寫-115年數據'!I140 -> 0 | J9: ='每日填寫-115年數據'!J140 -> 0 | ... Z9: ='每日填寫-115年數據'!Z140 -> 0
B10: 115/6 | C10: ='每日填寫-115年數據'!C175 -> 0 | D10: ='每日填寫-115年數據'!D175 -> 0 | E10: ='每日填寫-115年數據'!E175 -> 0 | F10: ='每日填寫-115年數據'!F175 -> 0 | G10: ='每日填寫-115年數據'!G175 -> 0 | H10: ='每日填寫-115年數據'!H175 -> 0 | I10: ='每日填寫-115年數據'!I175 -> 0 | J10: ='每日填寫-115年數據'!J175 -> 0 | ... Z10: ='每日填寫-115年數據'!Z175 -> 0
B11: 115/7 | C11: ='每日填寫-115年數據'!C209 -> 0 | D11: ='每日填寫-115年數據'!D209 -> 0 | E11: ='每日填寫-115年數據'!E209 -> 0 | F11: ='每日填寫-115年數據'!F209 -> 0 | G11: ='每日填寫-115年數據'!G209 -> 0 | H11: ='每日填寫-115年數據'!H209 -> 0 | I11: ='每日填寫-115年數據'!I209 -> 0 | J11: ='每日填寫-115年數據'!J209 -> 0 | ... Z11: ='每日填寫-115年數據'!Z209 -> 0
B12: 115/8 | C12: ='每日填寫-115年數據'!C244 -> 0 | D12: ='每日填寫-115年數據'!D244 -> 0 | E12: ='每日填寫-115年數據'!E244 -> 0 | F12: ='每日填寫-115年數據'!F244 -> 0 | G12: ='每日填寫-115年數據'!G244 -> 0 | H12: ='每日填寫-115年數據'!H244 -> 0 | I12: ='每日填寫-115年數據'!I244 -> 0 | J12: ='每日填寫-115年數據'!J244 -> 0 | ... Z12: ='每日填寫-115年數據'!Z244 -> 0
B13: 115/9 | C13: ='每日填寫-115年數據'!C279 -> 0 | D13: ='每日填寫-115年數據'!D279 -> 0 | E13: ='每日填寫-115年數據'!E279 -> 0 | F13: ='每日填寫-115年數據'!F279 -> 0 | G13: ='每日填寫-115年數據'!G279 -> 0 | H13: ='每日填寫-115年數據'!H279 -> 0 | I13: ='每日填寫-115年數據'!I279 -> 0 | J13: ='每日填寫-115年數據'!J279 -> 0 | ... Z13: ='每日填寫-115年數據'!Z279 -> 0
B14: 115/10 | C14: ='每日填寫-115年數據'!C313 -> 0 | D14: ='每日填寫-115年數據'!D313 -> 0 | E14: ='每日填寫-115年數據'!E313 -> 0 | F14: ='每日填寫-115年數據'!F313 -> 0 | G14: ='每日填寫-115年數據'!G313 -> 0 | H14: ='每日填寫-115年數據'!H313 -> 0 | I14: ='每日填寫-115年數據'!I313 -> 0 | J14: ='每日填寫-115年數據'!J313 -> 0 | ... Z14: ='每日填寫-115年數據'!Z313 -> 0
B15: 115/11 | C15: ='每日填寫-115年數據'!C348 -> 0 | D15: ='每日填寫-115年數據'!D348 -> 0 | E15: ='每日填寫-115年數據'!E348 -> 0 | F15: ='每日填寫-115年數據'!F348 -> 0 | G15: ='每日填寫-115年數據'!G348 -> 0 | H15: ='每日填寫-115年數據'!H348 -> 0 | I15: ='每日填寫-115年數據'!I348 -> 0 | J15: ='每日填寫-115年數據'!J348 -> 0 | ... Z15: ='每日填寫-115年數據'!Z348 -> 0
B16: 115/12 | C16: ='每日填寫-115年數據'!C382 -> 0 | D16: ='每日填寫-115年數據'!D382 -> 0 | E16: ='每日填寫-115年數據'!E382 -> 0 | F16: ='每日填寫-115年數據'!F382 -> 0 | G16: ='每日填寫-115年數據'!G382 -> 0 | H16: ='每日填寫-115年數據'!H382 -> 0 | I16: ='每日填寫-115年數據'!I382 -> 0 | J16: ='每日填寫-115年數據'!J382 -> 0 | ... Z16: ='每日填寫-115年數據'!Z382 -> 0

Sheet 每日填寫-115年數據
C2: 垃圾進廠量 (公噸) | G2: 燃燒量(公噸) | J2: 熱值(仟卡) | L2: 蒸汽量(T/H) | N2: 電力(MWh) | R2: 化學藥品使用量(公斤) | U2: 日常使用量 | Y2: 廢棄物運出(公噸) | AA2: 本月備註說明 (異常、起停爐)
C3: 公所 | D3: 轉運 | E3: 事廢 | F3: 本月進廠量 | G3: 一號爐 | H3: 二號爐 | I3: 合計 | J3: 一號爐 | K3: 二號爐 | L3: 一號爐 | M3: 二號爐 | N3: 發電量 | O3: 售電量 | P3: 廠內用電 | Q3: 售電率 | R3: 消石灰 | S3: 活性碳 | T3: 尿素 | U3: 柴油(公升) | V3: 純水(公噸) | W3: 自來水用表(公噸) | X3: 電表 | Y3: 底渣 | Z3: 飛灰
B4: 1月 | C4: =SUM(C5:C35) -> 3049.06 | D4: =SUM(D5:D35) -> 4855.29 | E4: =SUM(E5:E35) -> 719.28 | F4: =SUM(F5:F35) -> 8623.63 | G4: =SUM(G5:G35) -> 3690.04 | H4: =SUM(H5:H35) -> 3988.31 | I4: =SUM(I5:I35) -> 7678.35 | J4: =IFERROR(AVERAGE(J5:J35),0) -> 1940.0003 | K4: =IFERROR(AVERAGE(K5:K35),0) -> 2086.2145 | L4: =IFERROR(AVERAGE(L5:L35),0) -> 14.202581 | M4: =IFERROR(AVERAGE(M5:M35),0) -> 16.522258 | N4: =SUM(N5:N35) -> 3851.52 | O4: =SUM(O5:O35) -> 3180 | P4: =SUM(P5:P35) -> 671.52 | Q4: =IFERROR(O4/N4*100,0) -> 82.564806 | R4: =SUM(R5:R35) -> 85868 | S4: =SUM(S5:S35) -> 1488 | T4: =SUM(T5:T35) -> 11089 | U4: =SUM(U5:U35) -> 210 | V4: =SUM(V5:V35) -> 1498.53 | W4: =SUM(W5:W35) -> 2133 | X4: =SUM(X5:X35) -> 0 | Y4: =SUM(Y5:Y35) -> 388.52 | Z4: =SUM(Z5:Z35) -> 312.08
B5: 46023 | C5: 126.1 | D5: 0 | E5: 15.12 | F5: =SUM(C5:E5) -> 141.22 | G5: 101.02 | H5: 130.28 | I5: =SUM(G5:H5) -> 231.3 | J5: 1821.1 | K5: 2080.51 | L5: 12.28 | M5: 16.43 | N5: 113.04 | O5: 91.44 | P5: 21.6 | Q5: =O5/N5*100 -> 80.89172 | R5: 2932 | S5: 48 | T5: 280 | U5: 0 | V5: 47.39 | W5: 58 | X5: 0 | Y5: 0 | Z5: 0 | AA5: 1.
B6: 46024 | C6: 114.21 | D6: 0 | E6: 23.71 | F6: =SUM(C6:E6) -> 137.92 | G6: 97.32 | H6: 130.04 | I6: =SUM(G6:H6) -> 227.36 | J6: 1779.35 | K6: 2057.79 | L6: 11.71 | M6: 16.03 | N6: 110.4 | O6: 88.8 | P6: 21.6 | Q6: =O6/N6*100 -> 80.434783 | R6: 2714 | S6: 48 | T6: 377 | U6: 0 | V6: 39.82 | W6: 61 | X6: 0 | Y6: 0 | Z6: 0 | AA6: 2.
B7: 46025 | C7: 100.81 | D7: 0 | E7: 16.24 | F7: =SUM(C7:E7) -> 117.05 | G7: 100.9 | H7: 119.16 | I7: =SUM(G7:H7) -> 220.06 | J7: 1813.4 | K7: 2069.89 | L7: 12.2 | M7: 16.26 | N7: 113.52 | O7: 91.44 | P7: 22.08 | Q7: =O7/N7*100 -> 80.549683 | R7: 2800 | S7: 48 | T7: 240 | U7: 0 | V7: 50.47 | W7: 57 | X7: 0 | Y7: 0 | Z7: 0 | AA7: 3.
B8: 46026 | C8: 0 | D8: 0 | E8: 0 | F8: =SUM(C8:E8) -> 0 | G8: 116.62 | H8: 130.75 | I8: =SUM(G8:H8) -> 247.37 | J8: 1862.11 | K8: 2059.27 | L8: 12.94 | M8: 16.09 | N8: 114.72 | O8: 92.88 | P8: 21.84 | Q8: =O8/N8*100 -> 80.962343 | R8: 2507 | S8: 48 | T8: 456 | U8: 0 | V8: 42.31 | W8: 139 | X8: 0 | Y8: 0 | Z8: 0 | AA8: 4.
B9: 46027 | C9: 162.42 | D9: 168.67 | E9: 34.93 | F9: =SUM(C9:E9) -> 366.02 | G9: 113.53 | H9: 123.26 | I9: =SUM(G9:H9) -> 236.79 | J9: 1891.5 | K9: 2093.02 | L9: 13.42 | M9: 16.62 | N9: 119.76 | O9: 97.68 | P9: 22.08 | Q9: =O9/N9*100 -> 81.563126 | R9: 2795 | S9: 48 | T9: 340 | U9: 0 | V9: 41.11 | W9: 52 | X9: 0 | Y9: 0 | Z9: 0 | AA9: 5.
B10: 46028 | C10: 133.92 | D10: 240 | E10: 32.67 | F10: =SUM(C10:E10) -> 406.59 | G10: 109.43 | H10: 122.52 | I10: =SUM(G10:H10) -> 231.95 | J10: 1858.53 | K10: 2018.31 | L10: 12.92 | M10: 15.44 | N10: 112.56 | O10: 90.96 | P10: 21.6 | Q10: =O10/N10*100 -> 80.810235 | R10: 2897 | S10: 48 | T10: 446 | U10: 0 | V10: 50.95 | W10: 56 | X10: 0 | Y10: 0 | Z10: 0 | AA10: 6.
B11: 46029 | C11: 10.55 | D11: 146.57 | E11: 11.6 | F11: =SUM(C11:E11) -> 168.72 | G11: 114.89 | H11: 135.25 | I11: =SUM(G11:H11) -> 250.14 | J11: 1910.66 | K11: 2088.73 | L11: 13.74 | M11: 16.55 | N11: 124.08 | O11: 102.48 | P11: 21.6 | Q11: =O11/N11*100 -> 82.591876 | R11: 2739 | S11: 48 | T11: 258 | U11: 0 | V11: 38.18 | W11: 32 | X11: 0 | Y11: 0 | Z11: 0 | AA11: 7.
B12: 46030 | C12: 138.61 | D12: 165 | E12: 22.45 | F12: =SUM(C12:E12) -> 326.06 | G12: 116.55 | H12: 117.58 | I12: =SUM(G12:H12) -> 234.13 | J12: 1995.46 | K12: 2065.85 | L12: 15.09 | M12: 16.22 | N12: 131.28 | O12: 110.64 | P12: 20.64 | Q12: =O12/N12*100 -> 84.277879 | R12: 2704 | S12: 48 | T12: 407 | U12: 0 | V12: 48.24 | W12: 98 | X12: 0 | Y12: 0 | Z12: 0 | AA12: 8.
B13: 46031 | C13: 94.53 | D13: 201.81 | E13: 31.42 | F13: =SUM(C13:E13) -> 327.76 | G13: 126.32 | H13: 125.21 | I13: =SUM(G13:H13) -> 251.53 | J13: 1952.14 | K13: 2034.18 | L13: 14.4 | M13: 15.71 | N13: 124.32 | O13: 103.68 | P13: 20.64 | Q13: =O13/N13*100 -> 83.397683 | R13: 2694 | S13: 48 | T13: 288 | U13: 210 | V13: 49.7 | W13: 65 | X13: 0 | Y13: 0 | Z13: 0 | AA13: 9.
B14: 46032 | C14: 92.14 | D14: 91.21 | E14: 11.91 | F14: =SUM(C14:E14) -> 195.26 | G14: 125.34 | H14: 127.95 | I14: =SUM(G14:H14) -> 253.29 | J14: 1983.91 | K14: 2064.7 | L14: 14.89 | M14: 16.17 | N14: 126 | O14: 104.88 | P14: 21.12 | Q14: =O14/N14*100 -> 83.238095 | R14: 2583 | S14: 48 | T14: 365 | U14: 0 | V14: 49.7 | W14: 66 | X14: 0 | Y14: 0 | Z14: 0 | AA14: 10.
B15: 46033 | C15: 0 | D15: 0 | E15: 0 | F15: =SUM(C15:E15) -> 0 | G15: 118.55 | H15: 125.36 | I15: =SUM(G15:H15) -> 243.91 | J15: 1943.29 | K15: 2050.91 | L15: 14.24 | M15: 15.97 | N15: 123.36 | O15: 102.48 | P15: 20.88 | Q15: =O15/N15*100 -> 83.07393 | R15: 2496 | S15: 48 | T15: 307 | U15: 0 | V15: 56.59 | W15: 61 | X15: 0 | Y15: 0 | Z15: 0 | AA15: 11.
B16: 46034 | C16: 165.67 | D16: 146.3 | E16: 29.63 | F16: =SUM(C16:E16) -> 341.6 | G16: 122.71 | H16: 126.16 | I16: =SUM(G16:H16) -> 248.87 | J16: 1950.74 | K16: 2052.36 | L16: 14.38 | M16: 15.99 | N16: 124.08 | O16: 103.2 | P16: 20.88 | Q16: =O16/N16*100 -> 83.172147 | R16: 2552 | S16: 48 | T16: 392 | U16: 0 | V16: 35.16 | W16: 53 | X16: 0 | Y16: 0 | Z16: 0 | AA16: 12.
... B35: 46053 | C35: 102.56 | D35: 152.52 | E35: 15.59 | F35: =SUM(C35:E35) -> 270.67 | G35: 122.65 | H35: 126.47 | I35: =SUM(G35:H35) -> 249.12 | J35: 1978.59 | K35: 2110.44 | L35: 14.82 | M35: 16.91 | N35: 127.2 | O35: 103.92 | P35: 23.28 | Q35: =O35/N35*100 -> 81.698113 | R35: 3388 | S35: 48 | T35: 255 | U35: 0 | V35: 47.21 | W35: 66 | X35: 0 | Y35: 0 | Z35: 0 | AA35: 31.
C37: 垃圾進廠量 (公噸) | G37: 燃燒量(公噸) | J37: 熱值(仟卡) | L37: 蒸汽量(T/H) | N37: 電力(MWh) | R37: 化學藥品使用量(公斤) | U37: 日常使用量 | Y37: 廢棄物運出(公噸) | AA37: 本月備註說明 (異常、起停爐)
C38: 公所 | D38: 轉運 | E38: 事廢 | F38: 本月進廠量 | G38: 一號爐 | H38: 二號爐 | I38: 合計 | J38: 一號爐 | K38: 二號爐 | L38: 一號爐 | M38: 二號爐 | N38: 發電量 | O38: 售電量 | P38: 廠內用電 | Q38: 售電率 | R38: 消石灰 | S38: 活性碳 | T38: 尿素 | U38: 柴油(公升) | V38: 純水(公噸) | W38: 自來水用表(公噸) | X38: 電表 | Y38: 底渣 | Z38: 飛灰
B39: 2月 | C39: =SUM(C40:C67) -> 196.87 | D39: =SUM(D40:D67) -> 244.08 | E39: =SUM(E40:E67) -> 41.74 | F39: =SUM(F40:F67) -> 482.69 | G39: =SUM(G40:G67) -> 125.86 | H39: =SUM(H40:H67) -> 131.6 | I39: =SUM(I40:I67) -> 257.46 | J39: =IFERROR(AVERAGE(J40:J67),0) -> 2010.77 | K39: =IFERROR(AVERAGE(K40:K67),0) -> 2124.05 | L39: =IFERROR(AVERAGE(L40:L67),0) -> 15.33 | M39: =IFERROR(AVERAGE(M40:M67),0) -> 17.11 | N39: =SUM(N40:N67) -> 132 | O39: =SUM(O40:O67) -> 108.96 | P39: =SUM(P40:P67) -> 23.04 | Q39: =IFERROR(O39/N39*100,0) -> 82.545455 | R39: =SUM(R40:R67) -> 2932 | S39: =SUM(S40:S67) -> 48 | T39: =SUM(T40:T67) -> 394 | U39: =SUM(U40:U67) -> 0 | V39: =SUM(V40:V67) -> 55.71 | W39: =SUM(W40:W67) -> 67 | X39: =SUM(X40:X67) -> 0 | Y39: =SUM(Y40:Y67) -> 0 | Z39: =SUM(Z40:Z67) -> 0
B40: 46054 | C40: 0 | D40: 0 | E40: 0 | F40: =SUM(C40:E40) -> 0 | G40: 125.86 | H40: 131.6 | I40: =SUM(G40:H40) -> 257.46 | J40: 2010.77 | K40: 2124.05 | L40: 15.33 | M40: 17.11 | N40: 132 | O40: 108.96 | P40: 23.04 | Q40: =O40/N40*100 -> 82.545455 | R40: 2932 | S40: 48 | T40: 394 | U40: 0 | V40: 55.71 | W40: 67 | X40: 0 | Y40: 0 | Z40: 0 | AA40: 1.
B41: 46055 | C41: 196.87 | D41: 244.08 | E41: 41.74 | F41: =SUM(C41:E41) -> 482.69 | I41: =SUM(G41:H41) -> 0 | Q41: =O41/N41*100 -> #DIV/0! | AA41: 2.
B42: 46056 | F42: =SUM(C42:E42) -> 0 | I42: =SUM(G42:H42) -> 0 | Q42: =O42/N42*100 -> #DIV/0! | AA42: 3.
B43: 46057 | F43: =SUM(C43:E43) -> 0 | I43: =SUM(G43:H43) -> 0 | Q43: =O43/N43*100 -> #DIV/0! | AA43: 4.
B44: 46058 | F44: =SUM(C44:E44) -> 0 | I44: =SUM(G44:H44) -> 0 | Q44: =O44/N44*100 -> #DIV/0! | AA44: 5.
B45: 46059 | F45: =SUM(C45:E45) -> 0 | I45: =SUM(G45:H45) -> 0 | Q45: =O45/N45*100 -> #DIV/0! | AA45: 6.
B46: 46060 | F46: =SUM(C46:E46) -> 0 | I46: =SUM(G46:H46) -> 0 | Q46: =O46/N46*100 -> #DIV/0! | AA46: 7.
B47: 46061 | F47: =SUM(C47:E47) -> 0 | I47: =SUM(G47:H47) -> 0 | Q47: =O47/N47*100 -> #DIV/0! | AA47: 8.
B48: 46062 | F48: =SUM(C48:E48) -> 0 | I48: =SUM(G48:H48) -> 0 | Q48: =O48/N48*100 -> #DIV/0! | AA48: 9.
B49: 46063 | F49: =SUM(C49:E49) -> 0 | I49: =SUM(G49:H49) -> 0 | Q49: =O49/N49*100 -> #DIV/0! | AA49: 10.
B50: 46064 | F50: =SUM(C50:E50) -> 0 | I50: =SUM(G50:H50) -> 0 | Q50: =O50/N50*100 -> #DIV/0! | AA50: 11.
B51: 46065 | F51: =SUM(C51:E51) -> 0 | I51: =SUM(G51:H51) -> 0 | Q51: =O51/N51*100 -> #DIV/0! | AA51: 12.
B52: 46066 | F52: =SUM(C52:E52) -> 0 | I52: =SUM(G52:H52) -> 0 | Q52: =O52/N52*100 -> #DIV/0! | AA52: 13.
B53: 46067 | F53: =SUM(C53:E53) -> 0 | I53: =SUM(G53:H53) -> 0 | Q53: =O53/N53*100 -> #DIV/0! | AA53: 14.
... B67: 46081 | F67: =SUM(C67:E67) -> 0 | I67: =SUM(G67:H67) -> 0 | Q67: =O67/N67*100 -> #DIV/0! | AA67: 28.
C69: 垃圾進廠量 (公噸) | G69: 燃燒量(公噸) | J69: 熱值(仟卡) | L69: 蒸汽量(T/H) | N69: 電力(MWh) | R69: 化學藥品使用量(公斤) | U69: 日常使用量 | Y69: 廢棄物運出(公噸) | AA69: 本月備註說明 (異常、起停爐)
C70: 公所 | D70: 轉運 | E70: 事廢 | F70: 本月進廠量 | G70: 一號爐 | H70: 二號爐 | I70: 合計 | J70: 一號爐 | K70: 二號爐 | L70: 一號爐 | M70: 二號爐 | N70: 發電量 | O70: 售電量 | P70: 廠內用電 | Q70: 售電率 | R70: 消石灰 | S70: 活性碳 | T70: 尿素 | U70: 柴油(公升) | V70: 純水(公噸) | W70: 自來水用表(公噸) | X70: 電表 | Y70: 底渣 | Z70: 飛灰
B71: 3月 | C71: =SUM(C72:C102) -> 0 | D71: =SUM(D72:D102) -> 0 | E71: =SUM(E72:E102) -> 0 | F71: =SUM(F72:F102) -> 0 | G71: =SUM(G72:G102) -> 0 | H71: =SUM(H72:H102) -> 0 | I71: =SUM(I72:I102) -> 0 | J71: =IFERROR(AVERAGE(J72:J102),0) -> 0 | K71: =IFERROR(AVERAGE(K72:K102),0) -> 0 | L71: =IFERROR(AVERAGE(L72:L102),0) -> 0 | M71: =IFERROR(AVERAGE(M72:M102),0) -> 0 | N71: =SUM(N72:N102) -> 0 | O71: =SUM(O72:O102) -> 0 | P71: =SUM(P72:P102) -> 0 | Q71: =IFERROR(O71/N71*100,0) -> 0 | R71: =SUM(R72:R102) -> 0 | S71: =SUM(S72:S102) -> 0 | T71: =SUM(T72:T102) -> 0 | U71: =SUM(U72:U102) -> 0 | V71: =SUM(V72:V102) -> 0 | W71: =SUM(W72:W102) -> 0 | X71: =SUM(X72:X102) -> 0 | Y71: =SUM(Y72:Y102) -> 0 | Z71: =SUM(Z72:Z102) -> 0
B72: 46082 | F72: =SUM(C72:E72) -> 0 | I72: =SUM(G72:H72) -> 0 | Q72: =O72/N72*100 -> #DIV/0! | AA72: 1.
B73: 46083 | F73: =SUM(C73:E73) -> 0 | I73: =SUM(G73:H73) -> 0 | Q73: =O73/N73*100 -> #DIV/0! | AA73: 2.
B74: 46084 | F74: =SUM(C74:E74) -> 0 | I74: =SUM(G74:H74) -> 0 | Q74: =O74/N74*100 -> #DIV/0! | AA74: 3.
...

Sheet 化學藥劑
C2: 廢水廠(公斤) | H2: 化學加藥(鍋爐) | L2: 純水廠 | N2: 本月備註說明
C3: 鹽酸 | D3: 氫氧化鈉 | E3: 次氯酸鈉 | F3: 助混凝劑 | G3: 混凝劑 | H3: 脫氧劑 | I3: 磷酸鈉 | J3: 腐蝕抑制劑 | K3: PH調節劑 | L3: 鹽酸 | M3: 氫氧化鈉
B4: 1月 | C4: =SUM(C5:C35) -> 30 | D4: =SUM(D5:D35) -> 75 | E4: =SUM(E5:E35) -> 50 | F4: =SUM(F5:F35) -> 0 | G4: =SUM(G5:G35) -> 40 | H4: =SUM(H5:H35) -> 50 | I4: =SUM(I5:I35) -> 75 | J4: =SUM(J5:J35) -> 0 | ... M4: =SUM(M5:M35) -> 2250
B5: 46023 | C5: 0 | D5: 0 | E5: 0 | F5: 0 | G5: 0 | H5: 0 | I5: 0 | J5: 0 | K5: 0 | L5: 150 | M5: 90 | N5: 1.
B6: 46024 | C6: 0 | D6: 0 | E6: 0 | F6: 0 | G6: 0 | H6: 0 | I6: 0 | J6: 0 | K6: 0 | L6: 0 | M6: 0 | N6: 2.
B7: 46025 | C7: 0 | D7: 0 | E7: 0 | F7: 0 | G7: 0 | H7: 0 | I7: 0 | J7: 0 | K7: 0 | L7: 0 | M7: 0 | N7: 3.
B8: 46026 | C8: 0 | D8: 0 | E8: 0 | F8: 0 | G8: 0 | H8: 0 | I8: 0 | J8: 0 | K8: 0 | L8: 0 | M8: 0 | N8: 4.
B9: 46027 | C9: 0 | D9: 0 | E9: 0 | F9: 0 | G9: 0 | H9: 0 | I9: 0 | J9: 0 | K9: 0 | L9: 0 | M9: 0 | N9: 5.
B10: 46028 | C10: 0 | D10: 0 | E10: 0 | F10: 0 | G10: 0 | H10: 0 | I10: 0 | J10: 0 | K10: 0 | L10: 0 | M10: 0 | N10: 6.
B11: 46029 | C11: 0 | D11: 0 | E11: 0 | F11: 0 | G11: 0 | H11: 0 | I11: 0 | J11: 0 | K11: 0 | L11: 240 | M11: 180 | N11: 7.
B12: 46030 | C12: 0 | D12: 0 | E12: 0 | F12: 0 | G12: 0 | H12: 0 | I12: 0 | J12: 0 | K12: 0 | L12: 240 | M12: 180 | N12: 8.
B13: 46031 | C13: 0 | D13: 0 | E13: 0 | F13: 0 | G13: 0 | H13: 25 | I13: 0 | J13: 0 | K13: 25 | L13: 240 | M13: 180 | N13: 9.
B14: 46032 | C14: 0 | D14: 0 | E14: 0 | F14: 0 | G14: 0 | H14: 0 | I14: 0 | J14: 0 | K14: 0 | L14: 270 | M14: 180 | N14: 10.
B15: 46033 | C15: 0 | D15: 0 | E15: 0 | F15: 0 | G15: 0 | H15: 0 | I15: 0 | J15: 0 | K15: 0 | L15: 0 | M15: 0 | N15: 11.
B16: 46034 | C16: 0 | D16: 25 | E16: 0 | F16: 0 | G16: 0 | H16: 0 | I16: 25 | J16: 0 | K16: 25 | L16: 0 | M16: 0 | N16: 12.
... B35: 46053 | C35: 0 | D35: 0 | E35: 25 | F35: 0 | G35: 20 | H35: 0 | I35: 0 | J35: 0 | K35: 25 | L35: 240 | M35: 180 | N35: 31.
C39: 廢水廠(公斤) | H39: 化學加藥(鍋爐) | L39: 純水廠 | N39: 本月備註說明
C40: 鹽酸 | D40: 氫氧化鈉 | E40: 次氯酸鈉 | F40: 助混凝劑 | G40: 混凝劑 | H40: 脫氧劑 | I40: 磷酸鈉 | J40: 腐蝕抑制劑 | K40: PH調節劑 | L40: 鹽酸 | M40: 氫氧化鈉
B41: 2月 | C41: =SUM(C42:C69) -> 0 | D41: =SUM(D42:D69) -> 0 | E41: =SUM(E42:E69) -> 0 | F41: =SUM(F42:F69) -> 0 | G41: =SUM(G42:G69) -> 0 | H41: =SUM(H42:H69) -> 25 | I41: =SUM(I42:I69) -> 25 | J41: =SUM(J42:J69) -> 0 | ... M41: =SUM(M42:M69) -> 90
B42: 46054 | C42: 0 | D42: 0 | E42: 0 | F42: 0 | G42: 0 | H42: 25 | I42: 25 | J42: 0 | K42: 0 | L42: 120 | M42: 90 | N42: 1.
B43: 46055 | N43: 2.
B44: 46056 | N44: 3.
B45: 46057 | N45: 4.
B46: 46058 | N46: 5.
B47: 46059 | N47: 6.
B48: 46060 | N48: 7.
B49: 46061 | N49: 8.
B50: 46062 | N50: 9.
B51: 46063 | N51: 10.
B52: 46064 | N52: 11.
B53: 46065 | N53: 12.
B54: 46066 | N54: 13.
... B69: 46081 | N69: 31.
C73: 廢水廠(公斤) | H73: 化學加藥(鍋爐) | L73: 純水廠 | N73: 本月備註說明
C74: 鹽酸 | D74: 氫氧化鈉 | E74: 次氯酸鈉 | F74: 助混凝劑 | G74: 混凝劑 | H74: 脫氧劑 | I74: 磷酸鈉 | J74: 腐蝕抑制劑 | K74: PH調節劑 | L74: 鹽酸 | M74: 氫氧化鈉
B75: 3月 | C75: =SUM(C76:C106) -> 0 | D75: =SUM(D76:D106) -> 0 | E75: =SUM(E76:E106) -> 0 | F75: =SUM(F76:F106) -> 0 | G75: =SUM(G76:G106) -> 0 | H75: =SUM(H76:H106) -> 0 | I75: =SUM(I76:I106) -> 0 | J75: =SUM(J76:J106) -> 0 | ... M75: =SUM(M76:M106) -> 0
B76: 46082 | N76: 1.
B77: 46083 | N77: 2.
B78: 46084 | N78: 3.
B79: 46085 | N79: 4.
...

Sheet 廠內飛灰存量變化
B2: 清運車趟 | C2: 1月 | E2: 46023 | F2: 46024 | G2: 46025 | H2: 46026 | I2: 46027 | J2: 46028 | K2: 46029 | L2: 46030 | M2: 46031 | N2: 46032 | O2: 46033 | P2: 46034 | Q2: 46035 | R2: 46036 | S2: 46037 | T2: 46038 | U2: 46039 | V2: 46040 | W2: 46041 | X2: 46042 | Y2: 46043 | Z2: 46044 | AA2: 46045 | AB2: 46046 | AC2: 46047 | AD2: 46048 | AE2: 46049 | AF2: 46050 | AG2: 46051 | AH2: 46052 | AI2: 46053
B3: 0 | C3: 產出包數 | D3: =SUM(E3:AI3) -> 259 | E3: 9 | F3: 0 | G3: 0 | H3: 0 | I3: 25 | J3: 11 | K3: 0 | L3: 0 | M3: 0 | N3: 0 | O3: 0 | P3: 20 | Q3: 20 | R3: 20 | S3: 15 | T3: 0 | U3: 0 | V3: 0 | W3: 20 | X3: 20 | Y3: 13 | Z3: 0 | AA3: 16 | AB3: 0 | AC3: 0 | AD3: 14 | AE3: 14 | AF3: 14 | AG3: 14 | AH3: 0 | AI3: 14
B4: 廠內剩餘 | C4: 運出包數 | D4: =SUM(E4:AI4) -> 0 | E4: 0 | F4: 0 | G4: 0 | H4: 0 | I4: 0 | J4: 0 | K4: 0 | L4: 0 | M4: 0 | N4: 0 | O4: 0 | P4: 0 | Q4: 0 | R4: 0 | S4: 0 | T4: 0 | U4: 0 | V4: 0 | W4: 0 | X4: 0 | Y4: 0 | Z4: 0 | AA4: 0 | AB4: 0 | AC4: 0 | AD4: 0 | AE4: 0 | AF4: 0 | AG4: 0 | AH4: 0 | AI4: 0
B5: =LOOKUP(1,1/(E5:AI5<>""),E5:AI5) -> 1073 | C5: 當日廠內包數 | E5: 823 | F5: =E5+F3-F4 -> 823 | G5: =F5+G3-G4 -> 823 | H5: =G5+H3-H4 -> 823 | I5: =H5+I3-I4 -> 848 | J5: =I5+J3-J4 -> 859 | K5: =J5+K3-K4 -> 859 | L5: =K5+L3-L4 -> 859 | M5: =L5+M3-M4 -> 859 | ... AI5: =AH5+AI3-AI4 -> 1073
B6: 每包均重 | C6: 當日清運重量 | D6: =SUM(E6:AH6) -> 312.08 | E6: {=TRANSPOSE('每日填寫-115年數據'!Z5:Z35)} -> 0 | F6: 0 | G6: 0 | H6: 0 | I6: 0 | J6: 0 | K6: 0 | L6: 0 | M6: 0 | N6: 0 | O6: 0 | P6: 0 | Q6: 0 | R6: 0 | S6: 0 | T6: 0 | U6: 0 | V6: 0 | W6: 0 | X6: 0 | Y6: 0 | Z6: 0 | AA6: 0 | AB6: 0 | AC6: 0 | AD6: 63.26 | AE6: 63.1 | AF6: 60.96 | AG6: 61.8 | AH6: 62.96 | AI6: 0
B7: =IFERROR(D6/D4*1000,) -> 0 | C7: 平均重量/包(KG) | E7: =IFERROR(E6/E4*1000,0) -> 0 | F7: =IFERROR(F6/F4*1000,0) -> 0 | G7: =IFERROR(G6/G4*1000,0) -> 0 | H7: =IFERROR(H6/H4*1000,0) -> 0 | I7: =IFERROR(I6/I4*1000,0) -> 0 | J7: =IFERROR(J6/J4*1000,0) -> 0 | K7: =IFERROR(K6/K4*1000,0) -> 0 | L7: =IFERROR(L6/L4*1000,0) -> 0 | ... AI7: =IFERROR(AI6/AI4*1000,0) -> 0
B8: 清運車趟 | C8: 2月 | E8: 46054 | F8: 46055 | G8: 46056 | H8: 46057 | I8: 46058 | J8: 46059 | K8: 46060 | L8: 46061 | M8: 46062 | N8: 46063 | O8: 46064 | P8: 46065 | Q8: 46066 | R8: 46067 | S8: 46068 | T8: 46069 | U8: 46070 | V8: 46071 | W8: 46072 | X8: 46073 | Y8: 46074 | Z8: 46075 | AA8: 46076 | AB8: 46077 | AC8: 46078 | AD8: 46079 | AE8: 46080 | AF8: 46081
B9: 9 | C9: 產出包數 | D9: =SUM(E9:AI9) -> 0 | E9: 0
B10: 廠內剩餘 | C10: 運出包數 | D10: =SUM(E10:AI10) -> 0 | E10: 0
B11: =LOOKUP(1,1/(E11:AI11<>""),E11:AI11) -> #N/A | C11: 當日廠內包數
B12: 每包均重 | C12: 當日清運重量 | D12: =SUM(E12:AG12) -> 0 | E12: {=TRANSPOSE('每日填寫-115年數據'!Z40:Z67)} -> 0 | F12: 0 | G12: 0 | H12: 0 | I12: 0 | J12: 0 | K12: 0 | L12: 0 | M12: 0 | N12: 0 | O12: 0 | P12: 0 | Q12: 0 | R12: 0 | S12: 0 | T12: 0 | U12: 0 | V12: 0 | W12: 0 | X12: 0 | Y12: 0 | Z12: 0 | AA12: 0 | AB12: 0 | AC12: 0 | AD12: 0 | AE12: 0 | AF12: 0
B13: =IFERROR(D12/D10*1000,0) -> 0 | C13: 平均重量/包(KG) | E13: =IFERROR(E12/E10*1000,0) -> 0 | F13: =IFERROR(F12/F10*1000,0) -> 0 | G13: =IFERROR(G12/G10*1000,0) -> 0 | H13: =IFERROR(H12/H10*1000,0) -> 0 | I13: =IFERROR(I12/I10*1000,0) -> 0 | J13: =IFERROR(J12/J10*1000,0) -> 0 | K13: =IFERROR(K12/K10*1000,0) -> 0 | L13: =IFERROR(L12/L10*1000,0) -> 0 | ... AF13: =IFERROR(AF12/AF10*1000,0) -> 0
B14: 清運車趟 | C14: 3月 | E14: 46082 | F14: 46083 | G14: 46084 | H14: 46085 | I14: 46086 | J14: 46087 | K14: 46088 | L14: 46089 | M14: 46090 | N14: 46091 | O14: 46092 | P14: 46093 | Q14: 46094 | R14: 46095 | S14: 46096 | T14: 46097 | U14: 46098 | V14: 46099 | W14: 46100 | X14: 46101 | Y14: 46102 | Z14: 46103 | AA14: 46104 | AB14: 46105 | AC14: 46106 | AD14: 46107 | AE14: 46108 | AF14: 46109 | AG14: 46110 | AH14: 46111 | AI14: 46112
B15: 0 | C15: 產出包數 | D15: =SUM(E15:AI15) -> 0
B16: 廠內剩餘 | C16: 運出包數 | D16: =SUM(E16:AI16) -> 0
B17: =LOOKUP(1,1/(E17:AI17<>""),E17:AI17) -> #N/A | C17: 當日廠內包數
B18: 每包均重 | C18: 當日清運重量 | D18: =SUM(E18:AI18) -> 0 | E18: {=TRANSPOSE('每日填寫-115年數據'!Z72:Z102)} -> 0 | F18: 0 | G18: 0 | H18: 0 | I18: 0 | J18: 0 | K18: 0 | L18: 0 | M18: 0 | N18: 0 | O18: 0 | P18: 0 | Q18: 0 | R18: 0 | S18: 0 | T18: 0 | U18: 0 | V18: 0 | W18: 0 | X18: 0 | Y18: 0 | Z18: 0 | AA18: 0 | AB18: 0 | AC18: 0 | AD18: 0 | AE18: 0 | AF18: 0 | AG18: 0 | AH18: 0 | AI18: 0
B19: =IFERROR(D18/D16*1000,0) -> 0 | C19: 平均重量/包(KG) | E19: =IFERROR(E18/E16*1000,0) -> 0 | F19: =IFERROR(F18/F16*1000,0) -> 0 | G19: =IFERROR(G18/G16*1000,0) -> 0 | H19: =IFERROR(H18/H16*1000,0) -> 0 | I19: =IFERROR(I18/I16*1000,0) -> 0 | J19: =IFERROR(J18/J16*1000,0) -> 0 | K19: =IFERROR(K18/K16*1000,0) -> 0 | L19: =IFERROR(L18/L16*1000,0) -> 0 | ... AI19: =IFERROR(AI18/AI16*1000,0) -> 0
B20: 清運車趟 | C20: 4月 | E20: 46113 | F20: 46114 | G20: 46115 | H20: 46116 | I20: 46117 | J20: 46118 | K20: 46119 | L20: 46120 | M20: 46121 | N20: 46122 | O20: 46123 | P20: 46124 | Q20: 46125 | R20: 46126 | S20: 46127 | T20: 46128 | U20: 46129 | V20: 46130 | W20: 46131 | X20: 46132 | Y20: 46133 | Z20: 46134 | AA20: 46135 | AB20: 46136 | AC20: 46137 | AD20: 46138 | AE20: 46139 | AF20: 46140 | AG20: 46141 | AH20: 46142
B21: 0 | C21: 產出包數 | D21: =SUM(E21:AI21) -> 0
B22: 廠內剩餘 | C22: 運出包數 | D22: =SUM(E22:AI22) -> 0
B23: =LOOKUP(1,1/(E23:AI23<>""),E23:AI23) -> #N/A | C23: 當日廠內包數
B24: 每包均重 | C24: 當日清運重量 | D24: =SUM(E24:AH24) -> 0 | E24: {=TRANSPOSE('每日填寫-115年數據'!Z107:Z136)} -> 0 | F24: 0 | G24: 0 | H24: 0 | I24: 0 | J24: 0 | K24: 0 | L24: 0 | M24: 0 | N24: 0 | O24: 0 | P24: 0 | Q24: 0 | R24: 0 | S24: 0 | T24: 0 | U24: 0 | V24: 0 | W24: 0 | X24: 0 | Y24: 0 | Z24: 0 | AA24: 0 | AB24: 0 | AC24: 0 | AD24: 0 | AE24: 0 | AF24: 0 | AG24: 0 | AH24: 0
B25: =IFERROR(D24/D22*1000,0) -> 0 | C25: 平均重量/包(KG) | E25: =IFERROR(E24/E22*1000,0) -> 0 | F25: =IFERROR(F24/F22*1000,0) -> 0 | G25: =IFERROR(G24/G22*1000,0) -> 0 | H25: =IFERROR(H24/H22*1000,0) -> 0 | I25: =IFERROR(I24/I22*1000,0) -> 0 | J25: =IFERROR(J24/J22*1000,0) -> 0 | K25: =IFERROR(K24/K22*1000,0) -> 0 | L25: =IFERROR(L24/L22*1000,0) -> 0 | ... AH25: =IFERROR(AH24/AH22*1000,0) -> 0
B26: 清運車趟 | C26: 5月 | E26: 46143 | F26: 46144 | G26: 46145 | H26: 46146 | I26: 46147 | J26: 46148 | K26: 46149 | L26: 46150 | M26: 46151 | N26: 46152 | O26: 46153 | P26: 46154 | Q26: 46155 | R26: 46156 | S26: 46157 | T26: 46158 | U26: 46159 | V26: 46160 | W26: 46161 | X26: 46162 | Y26: 46163 | Z26: 46164 | AA26: 46165 | AB26: 46166 | AC26: 46167 | AD26: 46168 | AE26: 46169 | AF26: 46170 | AG26: 46171 | AH26: 46172 | AI26: 46173
B27: 0 | C27: 產出包數 | D27: =SUM(E27:AI27) -> 0
B28: 廠內剩餘 | C28: 運出包數 | D28: =SUM(E28:AI28) -> 0
B29: =LOOKUP(1,1/(E29:AI29<>""),E29:AI29) -> #N/A | C29: 當日廠內包數
B30: 每包均重 | C30: 當日清運重量 | D30: =SUM(E30:AI30) -> 0
B31: =IFERROR(D30/D28*1000,0) -> 0 | C31: 平均重量/包(KG)
B32: 清運車趟 | C32: 6月 | E32: 46174 | F32: 46175 | G32: 46176 | H32: 46177 | I32: 46178 | J32: 46179 | K32: 46180 | L32: 46181 | M32: 46182 | N32: 46183 | O32: 46184 | P32: 46185 | Q32: 46186 | R32: 46187 | S32: 46188 | T32: 46189 | U32: 46190 | V32: 46191 | W32: 46192 | X32: 46193 | Y32: 46194 | Z32: 46195 | AA32: 46196 | AB32: 46197 | AC32: 46198 | AD32: 46199 | AE32: 46200 | AF32: 46201 | AG32: 46202 | AH32: 46203
B33: 0 | C33: 產出包數 | D33: =SUM(E33:AI33) -> 0
B34: 廠內剩餘 | C34: 運出包數 | D34: =SUM(E34:AI34) -> 0
B35: =LOOKUP(1,1/(E35:AI35<>""),E35:AI35) -> #N/A | C35: 當日廠內包數
B36: 每包均重 | C36: 當日清運重量 | D36: =SUM(E36:AH36) -> 0
B37: =IFERROR(D36/D34*1000,0) -> 0 | C37: 平均重量/包(KG)
B38: 清運車趟 | C38: 7月 | E38: 46204 | F38: 46205 | G38: 46206 | H38: 46207 | I38: 46208 | J38: 46209 | K38: 46210 | L38: 46211 | M38: 46212 | N38: 46213 | O38: 46214 | P38: 46215 | Q38: 46216 | R38: 46217 | S38: 46218 | T38: 46219 | U38: 46220 | V38: 46221 | W38: 46222 | X38: 46223 | Y38: 46224 | Z38: 46225 | AA38: 46226 | AB38: 46227 | AC38: 46228 | AD38: 46229 | AE38: 46230 | AF38: 46231 | AG38: 46232 | AH38: 46233 | AI38: 46234
B39: 0 | C39: 產出包數 | D39: =SUM(E39:AI39) -> 0
B40: 廠內剩餘 | C40: 運出包數 | D40: =SUM(E40:AI40) -> 0
B41: =LOOKUP(1,1/(E41:AI41<>""),E41:AI41) -> #N/A | C41: 當日廠內包數
...

Sheet 飛灰製程原料用量
B3: 1月份 | C3: 包數 | D3: 原灰 | E3: 水泥 | F3: 螯合劑 | G3: 水 | H3: 合計重量 | I3: 增重比 | J3: 單包重量 | L3: 2月份 | M3: 包數 | N3: 原灰 | O3: 水泥 | P3: 螯合劑 | Q3: 水 | R3: 合計重量 | S3: 增重比 | T3: 單包重量 | V3: 3月份 | W3: 包數 | X3: 原灰 | Y3: 水泥 | Z3: 螯合劑 | AA3: 水 | AB3: 合計重量 | AC3: 增重比 | AD3: 單包重量 | AF3: 4月份 | AG3: 包數 | AH3: 原灰 | AI3: 水泥 | AJ3: 螯合劑 | AK3: 水 | AL3: 合計重量 | AM3: 增重比 | AN3: 單包重量 | AP3: 5月份 | AQ3: 包數 | AR3: 原灰 | AS3: 水泥 | AT3: 螯合劑 | AU3: 水 | AV3: 合計重量 | AW3: 增重比 | AX3: 單包重量 | AZ3: 6月份 | BA3: 包數 | BB3: 原灰 | BC3: 水泥 | BD3: 螯合劑 | BE3: 水 | BF3: 合計重量 | BG3: 增重比 | BH3: 單包重量 | BJ3: 7月份 | BK3: 包數 | BL3: 原灰 | BM3: 水泥 | BN3: 螯合劑 | BO3: 水 | BP3: 合計重量 | BQ3: 增重比 | BR3: 單包重量 | BT3: 8月份 | BU3: 包數 | BV3: 原灰 | BW3: 水泥 | BX3: 螯合劑 | BY3: 水 | BZ3: 合計重量 | CA3: 增重比 | CB3: 單包重量 | CD3: 9月份 | CE3: 包數 | CF3: 原灰 | CG3: 水泥 | CH3: 螯合劑 | CI3: 水 | CJ3: 合計重量 | CK3: 增重比 | CL3: 單包重量 | CN3: 10月份 | CO3: 包數 | CP3: 原灰 | CQ3: 水泥 | CR3: 螯合劑 | CS3: 水 | CT3: 合計重量 | CU3: 增重比 | CV3: 單包重量 | CX3: 11月份 | CY3: 包數 | CZ3: 原灰 | DA3: 水泥 | DB3: 螯合劑 | DC3: 水 | DD3: 合計重量 | DE3: 增重比 | DF3: 單包重量 | DH3: 10月份 | DI3: 包數 | DJ3: 原灰 | DK3: 水泥 | DL3: 螯合劑 | DM3: 水 | DN3: 合計重量 | DO3: 增重比 | DP3: 單包重量
C4: =SUM(C5:C35) -> 259 | D4: =SUM(D5:D35) -> 181384 | E4: =SUM(E5:E35) -> 19754 | F4: =SUM(F5:F35) -> 6800 | G4: =SUM(G5:G35) -> 59284 | H4: =SUM(H5:H35) -> 267222 | I4: =H4/D4 -> 1.4732391 | J4: =H4/C4 -> 1031.7452 | M4: =SUM(M5:M32) -> 0 | N4: =SUM(N5:N32) -> 0 | O4: =SUM(O5:O32) -> 0 | P4: =SUM(P5:P32) -> 0 | Q4: =SUM(Q5:Q32) -> 0 | R4: =SUM(R5:R32) -> 0 | S4: =R4/N4 -> #DIV/0! | T4: =R4/M4 -> #DIV/0! | W4: =SUM(W5:W35) -> 0 | X4: =SUM(X5:X35) -> 0 | Y4: =SUM(Y5:Y35) -> 0 | Z4: =SUM(Z5:Z35) -> 0 | AA4: =SUM(AA5:AA35) -> 0 | AB4: =SUM(AB5:AB35) -> 0 | AC4: =AB4/X4 -> #DIV/0! | AD4: =AB4/W4 -> #DIV/0! | AG4: =SUM(AG5:AG35) -> 0 | AH4: =SUM(AH5:AH35) -> 0 | AI4: =SUM(AI5:AI35) -> 0 | AJ4: =SUM(AJ5:AJ35) -> 0 | AK4: =SUM(AK5:AK35) -> 0 | AL4: =SUM(AL5:AL35) -> 0 | AM4: =AL4/AH4 -> #DIV/0! | AN4: =AL4/AG4 -> #DIV/0! | AQ4: =SUM(AQ5:AQ35) -> 0 | AR4: =SUM(AR5:AR35) -> 0 | AS4: =SUM(AS5:AS35) -> 0 | AT4: =SUM(AT5:AT35) -> 0 | AU4: =SUM(AU5:AU35) -> 0 | AV4: =SUM(AV5:AV35) -> 0 | AW4: =AV4/AR4 -> #DIV/0! | AX4: =AV4/AQ4 -> #DIV/0! | BA4: =SUM(BA5:BA34) -> 0 | BB4: =SUM(BB5:BB34) -> 0 | BC4: =SUM(BC5:BC34) -> 0 | BD4: =SUM(BD5:BD34) -> 0 | BE4: =SUM(BE5:BE34) -> 0 | BF4: =SUM(BF5:BF34) -> 0 | BG4: =BF4/BB4 -> #DIV/0! | BH4: =BF4/BA4 -> #DIV/0! | BK4: =SUM(BK5:BK35) -> 0 | BL4: =SUM(BL5:BL35) -> 0 | BM4: =SUM(BM5:BM35) -> 0 | BN4: =SUM(BN5:BN35) -> 0 | BO4: =SUM(BO5:BO35) -> 0 | BP4: =SUM(BP5:BP35) -> 0 | BQ4: =BP4/BL4 -> #DIV/0! | BR4: =BP4/BK4 -> #DIV/0! | BU4: =SUM(BU5:BU35) -> 0 | BV4: =SUM(BV5:BV35) -> 0 | BW4: =SUM(BW5:BW35) -> 0 | BX4: =SUM(BX5:BX35) -> 0 | BY4: =SUM(BY5:BY35) -> 0 | BZ4: =SUM(BZ5:BZ35) -> 0 | CA4: =BZ4/BV4 -> #DIV/0! | CB4: =BZ4/BU4 -> #DIV/0! | CE4: =SUM(CE5:CE34) -> 0 | CF4: =SUM(CF5:CF34) -> 0 | CG4: =SUM(CG5:CG34) -> 0 | CH4: =SUM(CH5:CH34) -> 0 | CI4: =SUM(CI5:CI34) -> 0 | CJ4: =SUM(CJ5:CJ34) -> 0 | CK4: =CJ4/CF4 -> #DIV/0! | CL4: =CJ4/CE4 -> #DIV/0! | CO4: =SUM(CO5:CO35) -> 0 | CP4: =SUM(CP5:CP35) -> 0 | CQ4: =SUM(CQ5:CQ35) -> 0 | CR4: =SUM(CR5:CR35) -> 0 | CS4: =SUM(CS5:CS35) -> 0 | CT4: =SUM(CT5:CT35) -> 0 | CU4: =CT4/CP4 -> #DIV/0! | CV4: =CT4/CO4 -> #DIV/0! | CY4: =SUM(CY5:CY34) -> 0 | CZ4: =SUM(CZ5:CZ34) -> 0 | DA4: =SUM(DA5:DA34) -> 0 | DB4: =SUM(DB5:DB34) -> 0 | DC4: =SUM(DC5:DC34) -> 0 | DD4: =SUM(DD5:DD34) -> 0 | DE4: =DD4/CZ4 -> #DIV/0! | DF4: =DD4/CY4 -> #DIV/0! | DI4: =SUM(DI5:DI35) -> 0 | DJ4: =SUM(DJ5:DJ35) -> 0 | DK4: =SUM(DK5:DK35) -> 0 | DL4: =SUM(DL5:DL35) -> 0 | DM4: =SUM(DM5:DM35) -> 0 | DN4: =SUM(DN5:DN35) -> 0 | DO4: =DN4/DJ4 -> #DIV/0! | DP4: =DN4/DI4 -> #DIV/0!
B5: 46023 | C5: 9 | D5: 6191 | E5: 686 | F5: 231 | G5: 2018 | H5: =SUM(D5:G5) -> 9126 | I5: =IFERROR(H5/D5,0) -> 1.4740753 | J5: =IFERROR(H5/C5,0) -> 1014 | L5: 46054 | M5: 0 | N5: 0 | O5: 0 | P5: 0 | Q5: 0 | R5: =SUM(N5:Q5) -> 0 | S5: =IFERROR(R5/N5,0) -> 0 | T5: =IFERROR(R5/M5,0) -> 0 | V5: 46082 | AB5: =SUM(X5:AA5) -> 0 | AC5: =IFERROR(AB5/X5,0) -> 0 | AD5: =IFERROR(AB5/W5,0) -> 0 | AF5: 46113 | AL5: =SUM(AH5:AK5) -> 0 | AM5: =IFERROR(AL5/AH5,0) -> 0 | AN5: =IFERROR(AL5/AG5,0) -> 0 | AP5: 46143 | AV5: =SUM(AR5:AU5) -> 0 | AW5: =IFERROR(AV5/AR5,0) -> 0 | AX5: =IFERROR(AV5/AQ5,0) -> 0 | AZ5: 46174 | BF5: =SUM(BB5:BE5) -> 0 | BG5: =IFERROR(BF5/BB5,0) -> 0 | BH5: =IFERROR(BF5/BA5,0) -> 0 | BJ5: 46204 | BP5: =SUM(BL5:BO5) -> 0 | BQ5: =IFERROR(BP5/BL5,0) -> 0 | BR5: =IFERROR(BP5/BK5,0) -> 0 | BT5: 46235 | BZ5: =SUM(BV5:BY5) -> 0 | CA5: =IFERROR(BZ5/BV5,0) -> 0 | CB5: =IFERROR(BZ5/BU5,0) -> 0 | CD5: 46266 | CJ5: =SUM(CF5:CI5) -> 0 | CK5: =IFERROR(CJ5/CF5,0) -> 0 | CL5: =IFERROR(CJ5/CE5,0) -> 0 | CN5: 46296 | CT5: =SUM(CP5:CS5) -> 0 | CU5: =IFERROR(CT5/CP5,0) -> 0 | CV5: =IFERROR(CT5/CO5,0) -> 0 | CX5: 46327 | DD5: =SUM(CZ5:DC5) -> 0 | DE5: =IFERROR(DD5/CZ5,0) -> 0 | DF5: =IFERROR(DD5/CY5,0) -> 0 | DH5: 46357 | DN5: =SUM(DJ5:DM5) -> 0 | DO5: =IFERROR(DN5/DJ5,0) -> 0 | DP5: =IFERROR(DN5/DI5,0) -> 0
B6: 46024 | C6: 0 | D6: 0 | E6: 0 | F6: 0 | G6: 0 | H6: =SUM(D6:G6) -> 0 | I6: =IFERROR(H6/D6,0) -> 0 | J6: =IFERROR(H6/C6,0) -> 0 | L6: 46055 | R6: =SUM(N6:Q6) -> 0 | S6: =IFERROR(R6/N6,0) -> 0 | T6: =IFERROR(R6/M6,0) -> 0 | V6: 46083 | AB6: =SUM(X6:AA6) -> 0 | AC6: =IFERROR(AB6/X6,0) -> 0 | AD6: =IFERROR(AB6/W6,0) -> 0 | AF6: 46114 | AL6: =SUM(AH6:AK6) -> 0 | AM6: =IFERROR(AL6/AH6,0) -> 0 | AN6: =IFERROR(AL6/AG6,0) -> 0 | AP6: 46144 | AV6: =SUM(AR6:AU6) -> 0 | AW6: =IFERROR(AV6/AR6,0) -> 0 | AX6: =IFERROR(AV6/AQ6,0) -> 0 | AZ6: 46175 | BF6: =SUM(BB6:BE6) -> 0 | BG6: =IFERROR(BF6/BB6,0) -> 0 | BH6: =IFERROR(BF6/BA6,0) -> 0 | BJ6: 46205 | BP6: =SUM(BL6:BO6) -> 0 | BQ6: =IFERROR(BP6/BL6,0) -> 0 | BR6: =IFERROR(BP6/BK6,0) -> 0 | BT6: 46236 | BZ6: =SUM(BV6:BY6) -> 0 | CA6: =IFERROR(BZ6/BV6,0) -> 0 | CB6: =IFERROR(BZ6/BU6,0) -> 0 | CD6: 46267 | CJ6: =SUM(CF6:CI6) -> 0 | CK6: =IFERROR(CJ6/CF6,0) -> 0 | CL6: =IFERROR(CJ6/CE6,0) -> 0 | CN6: 46297 | CT6: =SUM(CP6:CS6) -> 0 | CU6: =IFERROR(CT6/CP6,0) -> 0 | CV6: =IFERROR(CT6/CO6,0) -> 0 | CX6: 46328 | DD6: =SUM(CZ6:DC6) -> 0 | DE6: =IFERROR(DD6/CZ6,0) -> 0 | DF6: =IFERROR(DD6/CY6,0) -> 0 | DH6: 46358 | DN6: =SUM(DJ6:DM6) -> 0 | DO6: =IFERROR(DN6/DJ6,0) -> 0 | DP6: =IFERROR(DN6/DI6,0) -> 0
B7: 46025 | C7: 0 | D7: 0 | E7: 0 | F7: 0 | G7: 0 | H7: =SUM(D7:G7) -> 0 | I7: =IFERROR(H7/D7,0) -> 0 | J7: =IFERROR(H7/C7,0) -> 0 | L7: 46056 | R7: =SUM(N7:Q7) -> 0 | S7: =IFERROR(R7/N7,0) -> 0 | T7: =IFERROR(R7/M7,0) -> 0 | V7: 46084 | AB7: =SUM(X7:AA7) -> 0 | AC7: =IFERROR(AB7/X7,0) -> 0 | AD7: =IFERROR(AB7/W7,0) -> 0 | AF7: 46115 | AL7: =SUM(AH7:AK7) -> 0 | AM7: =IFERROR(AL7/AH7,0) -> 0 | AN7: =IFERROR(AL7/AG7,0) -> 0 | AP7: 46145 | AV7: =SUM(AR7:AU7) -> 0 | AW7: =IFERROR(AV7/AR7,0) -> 0 | AX7: =IFERROR(AV7/AQ7,0) -> 0 | AZ7: 46176 | BF7: =SUM(BB7:BE7) -> 0 | BG7: =IFERROR(BF7/BB7,0) -> 0 | BH7: =IFERROR(BF7/BA7,0) -> 0 | BJ7: 46206 | BP7: =SUM(BL7:BO7) -> 0 | BQ7: =IFERROR(BP7/BL7,0) -> 0 | BR7: =IFERROR(BP7/BK7,0) -> 0 | BT7: 46237 | BZ7: =SUM(BV7:BY7) -> 0 | CA7: =IFERROR(BZ7/BV7,0) -> 0 | CB7: =IFERROR(BZ7/BU7,0) -> 0 | CD7: 46268 | CJ7: =SUM(CF7:CI7) -> 0 | CK7: =IFERROR(CJ7/CF7,0) -> 0 | CL7: =IFERROR(CJ7/CE7,0) -> 0 | CN7: 46298 | CT7: =SUM(CP7:CS7) -> 0 | CU7: =IFERROR(CT7/CP7,0) -> 0 | CV7: =IFERROR(CT7/CO7,0) -> 0 | CX7: 46329 | DD7: =SUM(CZ7:DC7) -> 0 | DE7: =IFERROR(DD7/CZ7,0) -> 0 | DF7: =IFERROR(DD7/CY7,0) -> 0 | DH7: 46359 | DN7: =SUM(DJ7:DM7) -> 0 | DO7: =IFERROR(DN7/DJ7,0) -> 0 | DP7: =IFERROR(DN7/DI7,0) -> 0
B8: 46026 | C8: 0 | D8: 0 | E8: 0 | F8: 0 | G8: 0 | H8: =SUM(D8:G8) -> 0 | I8: =IFERROR(H8/D8,0) -> 0 | J8: =IFERROR(H8/C8,0) -> 0 | L8: 46057 | R8: =SUM(N8:Q8) -> 0 | S8: =IFERROR(R8/N8,0) -> 0 | T8: =IFERROR(R8/M8,0) -> 0 | V8: 46085 | AB8: =SUM(X8:AA8) -> 0 | AC8: =IFERROR(AB8/X8,0) -> 0 | AD8: =IFERROR(AB8/W8,0) -> 0 | AF8: 46116 | AL8: =SUM(AH8:AK8) -> 0 | AM8: =IFERROR(AL8/AH8,0) -> 0 | AN8: =IFERROR(AL8/AG8,0) -> 0 | AP8: 46146 | AV8: =SUM(AR8:AU8) -> 0 | AW8: =IFERROR(AV8/AR8,0) -> 0 | AX8: =IFERROR(AV8/AQ8,0) -> 0 | AZ8: 46177 | BF8: =SUM(BB8:BE8) -> 0 | BG8: =IFERROR(BF8/BB8,0) -> 0 | BH8: =IFERROR(BF8/BA8,0) -> 0 | BJ8: 46207 | BP8: =SUM(BL8:BO8) -> 0 | BQ8: =IFERROR(BP8/BL8,0) -> 0 | BR8: =IFERROR(BP8/BK8,0) -> 0 | BT8: 46238 | BZ8: =SUM(BV8:BY8) -> 0 | CA8: =IFERROR(BZ8/BV8,0) -> 0 | CB8: =IFERROR(BZ8/BU8,0) -> 0 | CD8: 46269 | CJ8: =SUM(CF8:CI8) -> 0 | CK8: =IFERROR(CJ8/CF8,0) -> 0 | CL8: =IFERROR(CJ8/CE8,0) -> 0 | CN8: 46299 | CT8: =SUM(CP8:CS8) -> 0 | CU8: =IFERROR(CT8/CP8,0) -> 0 | CV8: =IFERROR(CT8/CO8,0) -> 0 | CX8: 46330 | DD8: =SUM(CZ8:DC8) -> 0 | DE8: =IFERROR(DD8/CZ8,0) -> 0 | DF8: =IFERROR(DD8/CY8,0) -> 0 | DH8: 46360 | DN8: =SUM(DJ8:DM8) -> 0 | DO8: =IFERROR(DN8/DJ8,0) -> 0 | DP8: =IFERROR(DN8/DI8,0) -> 0
B9: 46027 | C9: 25 | D9: 17603 | E9: 1907 | F9: 651 | G9: 6291 | H9: =SUM(D9:G9) -> 26452 | I9: =IFERROR(H9/D9,0) -> 1.5026984 | J9: =IFERROR(H9/C9,0) -> 1058.08 | L9: 46058 | R9: =SUM(N9:Q9) -> 0 | S9: =IFERROR(R9/N9,0) -> 0 | T9: =IFERROR(R9/M9,0) -> 0 | V9: 46086 | AB9: =SUM(X9:AA9) -> 0 | AC9: =IFERROR(AB9/X9,0) -> 0 | AD9: =IFERROR(AB9/W9,0) -> 0 | AF9: 46117 | AL9: =SUM(AH9:AK9) -> 0 | AM9: =IFERROR(AL9/AH9,0) -> 0 | AN9: =IFERROR(AL9/AG9,0) -> 0 | AP9: 46147 | AV9: =SUM(AR9:AU9) -> 0 | AW9: =IFERROR(AV9/AR9,0) -> 0 | AX9: =IFERROR(AV9/AQ9,0) -> 0 | AZ9: 46178 | BF9: =SUM(BB9:BE9) -> 0 | BG9: =IFERROR(BF9/BB9,0) -> 0 | BH9: =IFERROR(BF9/BA9,0) -> 0 | BJ9: 46208 | BP9: =SUM(BL9:BO9) -> 0 | BQ9: =IFERROR(BP9/BL9,0) -> 0 | BR9: =IFERROR(BP9/BK9,0) -> 0 | BT9: 46239 | BZ9: =SUM(BV9:BY9) -> 0 | CA9: =IFERROR(BZ9/BV9,0) -> 0 | CB9: =IFERROR(BZ9/BU9,0) -> 0 | CD9: 46270 | CJ9: =SUM(CF9:CI9) -> 0 | CK9: =IFERROR(CJ9/CF9,0) -> 0 | CL9: =IFERROR(CJ9/CE9,0) -> 0 | CN9: 46300 | CT9: =SUM(CP9:CS9) -> 0 | CU9: =IFERROR(CT9/CP9,0) -> 0 | CV9: =IFERROR(CT9/CO9,0) -> 0 | CX9: 46331 | DD9: =SUM(CZ9:DC9) -> 0 | DE9: =IFERROR(DD9/CZ9,0) -> 0 | DF9: =IFERROR(DD9/CY9,0) -> 0 | DH9: 46361 | DN9: =SUM(DJ9:DM9) -> 0 | DO9: =IFERROR(DN9/DJ9,0) -> 0 | DP9: =IFERROR(DN9/DI9,0) -> 0
B10: 46028 | C10: 11 | D10: 7737 | E10: 831 | F10: 277 | G10: 2741 | H10: =SUM(D10:G10) -> 11586 | I10: =IFERROR(H10/D10,0) -> 1.4974796 | J10: =IFERROR(H10/C10,0) -> 1053.2727 | L10: 46059 | R10: =SUM(N10:Q10) -> 0 | S10: =IFERROR(R10/N10,0) -> 0 | T10: =IFERROR(R10/M10,0) -> 0 | V10: 46087 | AB10: =SUM(X10:AA10) -> 0 | AC10: =IFERROR(AB10/X10,0) -> 0 | AD10: =IFERROR(AB10/W10,0) -> 0 | AF10: 46118 | AL10: =SUM(AH10:AK10) -> 0 | AM10: =IFERROR(AL10/AH10,0) -> 0 | AN10: =IFERROR(AL10/AG10,0) -> 0 | AP10: 46148 | AV10: =SUM(AR10:AU10) -> 0 | AW10: =IFERROR(AV10/AR10,0) -> 0 | AX10: =IFERROR(AV10/AQ10,0) -> 0 | AZ10: 46179 | BF10: =SUM(BB10:BE10) -> 0 | BG10: =IFERROR(BF10/BB10,0) -> 0 | BH10: =IFERROR(BF10/BA10,0) -> 0 | BJ10: 46209 | BP10: =SUM(BL10:BO10) -> 0 | BQ10: =IFERROR(BP10/BL10,0) -> 0 | BR10: =IFERROR(BP10/BK10,0) -> 0 | BT10: 46240 | BZ10: =SUM(BV10:BY10) -> 0 | CA10: =IFERROR(BZ10/BV10,0) -> 0 | CB10: =IFERROR(BZ10/BU10,0) -> 0 | CD10: 46271 | CJ10: =SUM(CF10:CI10) -> 0 | CK10: =IFERROR(CJ10/CF10,0) -> 0 | CL10: =IFERROR(CJ10/CE10,0) -> 0 | CN10: 46301 | CT10: =SUM(CP10:CS10) -> 0 | CU10: =IFERROR(CT10/CP10,0) -> 0 | CV10: =IFERROR(CT10/CO10,0) -> 0 | CX10: 46332 | DD10: =SUM(CZ10:DC10) -> 0 | DE10: =IFERROR(DD10/CZ10,0) -> 0 | DF10: =IFERROR(DD10/CY10,0) -> 0 | DH10: 46362 | DN10: =SUM(DJ10:DM10) -> 0 | DO10: =IFERROR(DN10/DJ10,0) -> 0 | DP10: =IFERROR(DN10/DI10,0) -> 0
B11: 46029 | C11: 0 | D11: 0 | E11: 0 | F11: 0 | G11: 0 | H11: =SUM(D11:G11) -> 0 | I11: =IFERROR(H11/D11,0) -> 0 | J11: =IFERROR(H11/C11,0) -> 0 | L11: 46060 | R11: =SUM(N11:Q11) -> 0 | S11: =IFERROR(R11/N11,0) -> 0 | T11: =IFERROR(R11/M11,0) -> 0 | V11: 46088 | AB11: =SUM(X11:AA11) -> 0 | AC11: =IFERROR(AB11/X11,0) -> 0 | AD11: =IFERROR(AB11/W11,0) -> 0 | AF11: 46119 | AL11: =SUM(AH11:AK11) -> 0 | AM11: =IFERROR(AL11/AH11,0) -> 0 | AN11: =IFERROR(AL11/AG11,0) -> 0 | AP11: 46149 | AV11: =SUM(AR11:AU11) -> 0 | AW11: =IFERROR(AV11/AR11,0) -> 0 | AX11: =IFERROR(AV11/AQ11,0) -> 0 | AZ11: 46180 | BF11: =SUM(BB11:BE11) -> 0 | BG11: =IFERROR(BF11/BB11,0) -> 0 | BH11: =IFERROR(BF11/BA11,0) -> 0 | BJ11: 46210 | BP11: =SUM(BL11:BO11) -> 0 | BQ11: =IFERROR(BP11/BL11,0) -> 0 | BR11: =IFERROR(BP11/BK11,0) -> 0 | BT11: 46241 | BZ11: =SUM(BV11:BY11) -> 0 | CA11: =IFERROR(BZ11/BV11,0) -> 0 | CB11: =IFERROR(BZ11/BU11,0) -> 0 | CD11: 46272 | CJ11: =SUM(CF11:CI11) -> 0 | CK11: =IFERROR(CJ11/CF11,0) -> 0 | CL11: =IFERROR(CJ11/CE11,0) -> 0 | CN11: 46302 | CT11: =SUM(CP11:CS11) -> 0 | CU11: =IFERROR(CT11/CP11,0) -> 0 | CV11: =IFERROR(CT11/CO11,0) -> 0 | CX11: 46333 | DD11: =SUM(CZ11:DC11) -> 0 | DE11: =IFERROR(DD11/CZ11,0) -> 0 | DF11: =IFERROR(DD11/CY11,0) -> 0 | DH11: 46363 | DN11: =SUM(DJ11:DM11) -> 0 | DO11: =IFERROR(DN11/DJ11,0) -> 0 | DP11: =IFERROR(DN11/DI11,0) -> 0
B12: 46030 | C12: 0 | D12: 0 | E12: 0 | F12: 0 | G12: 0 | H12: =SUM(D12:G12) -> 0 | I12: =IFERROR(H12/D12,0) -> 0 | J12: =IFERROR(H12/C12,0) -> 0 | L12: 46061 | R12: =SUM(N12:Q12) -> 0 | S12: =IFERROR(R12/N12,0) -> 0 | T12: =IFERROR(R12/M12,0) -> 0 | V12: 46089 | AB12: =SUM(X12:AA12) -> 0 | AC12: =IFERROR(AB12/X12,0) -> 0 | AD12: =IFERROR(AB12/W12,0) -> 0 | AF12: 46120 | AL12: =SUM(AH12:AK12) -> 0 | AM12: =IFERROR(AL12/AH12,0) -> 0 | AN12: =IFERROR(AL12/AG12,0) -> 0 | AP12: 46150 | AV12: =SUM(AR12:AU12) -> 0 | AW12: =IFERROR(AV12/AR12,0) -> 0 | AX12: =IFERROR(AV12/AQ12,0) -> 0 | AZ12: 46181 | BF12: =SUM(BB12:BE12) -> 0 | BG12: =IFERROR(BF12/BB12,0) -> 0 | BH12: =IFERROR(BF12/BA12,0) -> 0 | BJ12: 46211 | BP12: =SUM(BL12:BO12) -> 0 | BQ12: =IFERROR(BP12/BL12,0) -> 0 | BR12: =IFERROR(BP12/BK12,0) -> 0 | BT12: 46242 | BZ12: =SUM(BV12:BY12) -> 0 | CA12: =IFERROR(BZ12/BV12,0) -> 0 | CB12: =IFERROR(BZ12/BU12,0) -> 0 | CD12: 46273 | CJ12: =SUM(CF12:CI12) -> 0 | CK12: =IFERROR(CJ12/CF12,0) -> 0 | CL12: =IFERROR(CJ12/CE12,0) -> 0 | CN12: 46303 | CT12: =SUM(CP12:CS12) -> 0 | CU12: =IFERROR(CT12/CP12,0) -> 0 | CV12: =IFERROR(CT12/CO12,0) -> 0 | CX12: 46334 | DD12: =SUM(CZ12:DC12) -> 0 | DE12: =IFERROR(DD12/CZ12,0) -> 0 | DF12: =IFERROR(DD12/CY12,0) -> 0 | DH12: 46364 | DN12: =SUM(DJ12:DM12) -> 0 | DO12: =IFERROR(DN12/DJ12,0) -> 0 | DP12: =IFERROR(DN12/DI12,0) -> 0
B13: 46031 | C13: 0 | D13: 0 | E13: 0 | F13: 0 | G13: 0 | H13: =SUM(D13:G13) -> 0 | I13: =IFERROR(H13/D13,0) -> 0 | J13: =IFERROR(H13/C13,0) -> 0 | L13: 46062 | R13: =SUM(N13:Q13) -> 0 | S13: =IFERROR(R13/N13,0) -> 0 | T13: =IFERROR(R13/M13,0) -> 0 | V13: 46090 | AB13: =SUM(X13:AA13) -> 0 | AC13: =IFERROR(AB13/X13,0) -> 0 | AD13: =IFERROR(AB13/W13,0) -> 0 | AF13: 46121 | AL13: =SUM(AH13:AK13) -> 0 | AM13: =IFERROR(AL13/AH13,0) -> 0 | AN13: =IFERROR(AL13/AG13,0) -> 0 | AP13: 46151 | AV13: =SUM(AR13:AU13) -> 0 | AW13: =IFERROR(AV13/AR13,0) -> 0 | AX13: =IFERROR(AV13/AQ13,0) -> 0 | AZ13: 46182 | BF13: =SUM(BB13:BE13) -> 0 | BG13: =IFERROR(BF13/BB13,0) -> 0 | BH13: =IFERROR(BF13/BA13,0) -> 0 | BJ13: 46212 | BP13: =SUM(BL13:BO13) -> 0 | BQ13: =IFERROR(BP13/BL13,0) -> 0 | BR13: =IFERROR(BP13/BK13,0) -> 0 | BT13: 46243 | BZ13: =SUM(BV13:BY13) -> 0 | CA13: =IFERROR(BZ13/BV13,0) -> 0 | CB13: =IFERROR(BZ13/BU13,0) -> 0 | CD13: 46274 | CJ13: =SUM(CF13:CI13) -> 0 | CK13: =IFERROR(CJ13/CF13,0) -> 0 | CL13: =IFERROR(CJ13/CE13,0) -> 0 | CN13: 46304 | CT13: =SUM(CP13:CS13) -> 0 | CU13: =IFERROR(CT13/CP13,0) -> 0 | CV13: =IFERROR(CT13/CO13,0) -> 0 | CX13: 46335 | DD13: =SUM(CZ13:DC13) -> 0 | DE13: =IFERROR(DD13/CZ13,0) -> 0 | DF13: =IFERROR(DD13/CY13,0) -> 0 | DH13: 46365 | DN13: =SUM(DJ13:DM13) -> 0 | DO13: =IFERROR(DN13/DJ13,0) -> 0 | DP13: =IFERROR(DN13/DI13,0) -> 0
B14: 46032 | C14: 0 | D14: 0 | E14: 0 | F14: 0 | G14: 0 | H14: =SUM(D14:G14) -> 0 | I14: =IFERROR(H14/D14,0) -> 0 | J14: =IFERROR(H14/C14,0) -> 0 | L14: 46063 | R14: =SUM(N14:Q14) -> 0 | S14: =IFERROR(R14/N14,0) -> 0 | T14: =IFERROR(R14/M14,0) -> 0 | V14: 46091 | AB14: =SUM(X14:AA14) -> 0 | AC14: =IFERROR(AB14/X14,0) -> 0 | AD14: =IFERROR(AB14/W14,0) -> 0 | AF14: 46122 | AL14: =SUM(AH14:AK14) -> 0 | AM14: =IFERROR(AL14/AH14,0) -> 0 | AN14: =IFERROR(AL14/AG14,0) -> 0 | AP14: 46152 | AV14: =SUM(AR14:AU14) -> 0 | AW14: =IFERROR(AV14/AR14,0) -> 0 | AX14: =IFERROR(AV14/AQ14,0) -> 0 | AZ14: 46183 | BF14: =SUM(BB14:BE14) -> 0 | BG14: =IFERROR(BF14/BB14,0) -> 0 | BH14: =IFERROR(BF14/BA14,0) -> 0 | BJ14: 46213 | BP14: =SUM(BL14:BO14) -> 0 | BQ14: =IFERROR(BP14/BL14,0) -> 0 | BR14: =IFERROR(BP14/BK14,0) -> 0 | BT14: 46244 | BZ14: =SUM(BV14:BY14) -> 0 | CA14: =IFERROR(BZ14/BV14,0) -> 0 | CB14: =IFERROR(BZ14/BU14,0) -> 0 | CD14: 46275 | CJ14: =SUM(CF14:CI14) -> 0 | CK14: =IFERROR(CJ14/CF14,0) -> 0 | CL14: =IFERROR(CJ14/CE14,0) -> 0 | CN14: 46305 | CT14: =SUM(CP14:CS14) -> 0 | CU14: =IFERROR(CT14/CP14,0) -> 0 | CV14: =IFERROR(CT14/CO14,0) -> 0 | CX14: 46336 | DD14: =SUM(CZ14:DC14) -> 0 | DE14: =IFERROR(DD14/CZ14,0) -> 0 | DF14: =IFERROR(DD14/CY14,0) -> 0 | DH14: 46366 | DN14: =SUM(DJ14:DM14) -> 0 | DO14: =IFERROR(DN14/DJ14,0) -> 0 | DP14: =IFERROR(DN14/DI14,0) -> 0
B15: 46033 | C15: 0 | D15: 0 | E15: 0 | F15: 0 | G15: 0 | H15: =SUM(D15:G15) -> 0 | I15: =IFERROR(H15/D15,0) -> 0 | J15: =IFERROR(H15/C15,0) -> 0 | L15: 46064 | R15: =SUM(N15:Q15) -> 0 | S15: =IFERROR(R15/N15,0) -> 0 | T15: =IFERROR(R15/M15,0) -> 0 | V15: 46092 | AB15: =SUM(X15:AA15) -> 0 | AC15: =IFERROR(AB15/X15,0) -> 0 | AD15: =IFERROR(AB15/W15,0) -> 0 | AF15: 46123 | AL15: =SUM(AH15:AK15) -> 0 | AM15: =IFERROR(AL15/AH15,0) -> 0 | AN15: =IFERROR(AL15/AG15,0) -> 0 | AP15: 46153 | AV15: =SUM(AR15:AU15) -> 0 | AW15: =IFERROR(AV15/AR15,0) -> 0 | AX15: =IFERROR(AV15/AQ15,0) -> 0 | AZ15: 46184 | BF15: =SUM(BB15:BE15) -> 0 | BG15: =IFERROR(BF15/BB15,0) -> 0 | BH15: =IFERROR(BF15/BA15,0) -> 0 | BJ15: 46214 | BP15: =SUM(BL15:BO15) -> 0 | BQ15: =IFERROR(BP15/BL15,0) -> 0 | BR15: =IFERROR(BP15/BK15,0) -> 0 | BT15: 46245 | BZ15: =SUM(BV15:BY15) -> 0 | CA15: =IFERROR(BZ15/BV15,0) -> 0 | CB15: =IFERROR(BZ15/BU15,0) -> 0 | CD15: 46276 | CJ15: =SUM(CF15:CI15) -> 0 | CK15: =IFERROR(CJ15/CF15,0) -> 0 | CL15: =IFERROR(CJ15/CE15,0) -> 0 | CN15: 46306 | CT15: =SUM(CP15:CS15) -> 0 | CU15: =IFERROR(CT15/CP15,0) -> 0 | CV15: =IFERROR(CT15/CO15,0) -> 0 | CX15: 46337 | DD15: =SUM(CZ15:DC15) -> 0 | DE15: =IFERROR(DD15/CZ15,0) -> 0 | DF15: =IFERROR(DD15/CY15,0) -> 0 | DH15: 46367 | DN15: =SUM(DJ15:DM15) -> 0 | DO15: =IFERROR(DN15/DJ15,0) -> 0 | DP15: =IFERROR(DN15/DI15,0) -> 0
B16: 46034 | C16: 20 | D16: 13832 | E16: 1491 | F16: 507 | G16: 3927 | H16: =SUM(D16:G16) -> 19757 | I16: =IFERROR(H16/D16,0) -> 1.4283545 | J16: =IFERROR(H16/C16,0) -> 987.85 | L16: 46065 | R16: =SUM(N16:Q16) -> 0 | S16: =IFERROR(R16/N16,0) -> 0 | T16: =IFERROR(R16/M16,0) -> 0 | V16: 46093 | AB16: =SUM(X16:AA16) -> 0 | AC16: =IFERROR(AB16/X16,0) -> 0 | AD16: =IFERROR(AB16/W16,0) -> 0 | AF16: 46124 | AL16: =SUM(AH16:AK16) -> 0 | AM16: =IFERROR(AL16/AH16,0) -> 0 | AN16: =IFERROR(AL16/AG16,0) -> 0 | AP16: 46154 | AV16: =SUM(AR16:AU16) -> 0 | AW16: =IFERROR(AV16/AR16,0) -> 0 | AX16: =IFERROR(AV16/AQ16,0) -> 0 | AZ16: 46185 | BF16: =SUM(BB16:BE16) -> 0 | BG16: =IFERROR(BF16/BB16,0) -> 0 | BH16: =IFERROR(BF16/BA16,0) -> 0 | BJ16: 46215 | BP16: =SUM(BL16:BO16) -> 0 | BQ16: =IFERROR(BP16/BL16,0) -> 0 | BR16: =IFERROR(BP16/BK16,0) -> 0 | BT16: 46246 | BZ16: =SUM(BV16:BY16) -> 0 | CA16: =IFERROR(BZ16/BV16,0) -> 0 | CB16: =IFERROR(BZ16/BU16,0) -> 0 | CD16: 46277 | CJ16: =SUM(CF16:CI16) -> 0 | CK16: =IFERROR(CJ16/CF16,0) -> 0 | CL16: =IFERROR(CJ16/CE16,0) -> 0 | CN16: 46307 | CT16: =SUM(CP16:CS16) -> 0 | CU16: =IFERROR(CT16/CP16,0) -> 0 | CV16: =IFERROR(CT16/CO16,0) -> 0 | CX16: 46338 | DD16: =SUM(CZ16:DC16) -> 0 | DE16: =IFERROR(DD16/CZ16,0) -> 0 | DF16: =IFERROR(DD16/CY16,0) -> 0 | DH16: 46368 | DN16: =SUM(DJ16:DM16) -> 0 | DO16: =IFERROR(DN16/DJ16,0) -> 0 | DP16: =IFERROR(DN16/DI16,0) -> 0
B17: 46035 | C17: 20 | D17: 13835 | E17: 1459 | F17: 517 | G17: 4706 | H17: =SUM(D17:G17) -> 20517 | I17: =IFERROR(H17/D17,0) -> 1.482978 | J17: =IFERROR(H17/C17,0) -> 1025.85 | L17: 46066 | R17: =SUM(N17:Q17) -> 0 | S17: =IFERROR(R17/N17,0) -> 0 | T17: =IFERROR(R17/M17,0) -> 0 | V17: 46094 | AB17: =SUM(X17:AA17) -> 0 | AC17: =IFERROR(AB17/X17,0) -> 0 | AD17: =IFERROR(AB17/W17,0) -> 0 | AF17: 46125 | AL17: =SUM(AH17:AK17) -> 0 | AM17: =IFERROR(AL17/AH17,0) -> 0 | AN17: =IFERROR(AL17/AG17,0) -> 0 | AP17: 46155 | AV17: =SUM(AR17:AU17) -> 0 | AW17: =IFERROR(AV17/AR17,0) -> 0 | AX17: =IFERROR(AV17/AQ17,0) -> 0 | AZ17: 46186 | BF17: =SUM(BB17:BE17) -> 0 | BG17: =IFERROR(BF17/BB17,0) -> 0 | BH17: =IFERROR(BF17/BA17,0) -> 0 | BJ17: 46216 | BP17: =SUM(BL17:BO17) -> 0 | BQ17: =IFERROR(BP17/BL17,0) -> 0 | BR17: =IFERROR(BP17/BK17,0) -> 0 | BT17: 46247 | BZ17: =SUM(BV17:BY17) -> 0 | CA17: =IFERROR(BZ17/BV17,0) -> 0 | CB17: =IFERROR(BZ17/BU17,0) -> 0 | CD17: 46278 | CJ17: =SUM(CF17:CI17) -> 0 | CK17: =IFERROR(CJ17/CF17,0) -> 0 | CL17: =IFERROR(CJ17/CE17,0) -> 0 | CN17: 46308 | CT17: =SUM(CP17:CS17) -> 0 | CU17: =IFERROR(CT17/CP17,0) -> 0 | CV17: =IFERROR(CT17/CO17,0) -> 0 | CX17: 46339 | DD17: =SUM(CZ17:DC17) -> 0 | DE17: =IFERROR(DD17/CZ17,0) -> 0 | DF17: =IFERROR(DD17/CY17,0) -> 0 | DH17: 46369 | DN17: =SUM(DJ17:DM17) -> 0 | DO17: =IFERROR(DN17/DJ17,0) -> 0 | DP17: =IFERROR(DN17/DI17,0) -> 0
... B32: 46050 | C32: 14 | D32: 9904 | E32: 1096 | F32: 364 | G32: 3340 | H32: =SUM(D32:G32) -> 14704 | I32: =IFERROR(H32/D32,0) -> 1.4846527 | J32: =IFERROR(H32/C32,0) -> 1050.2857 | L32: 46081 | R32: =SUM(N32:Q32) -> 0 | S32: =IFERROR(R32/N32,0) -> 0 | T32: =IFERROR(R32/M32,0) -> 0 | V32: 46109 | AB32: =SUM(X32:AA32) -> 0 | AC32: =IFERROR(AB32/X32,0) -> 0 | AD32: =IFERROR(AB32/W32,0) -> 0 | AF32: 46140 | AL32: =SUM(AH32:AK32) -> 0 | AM32: =IFERROR(AL32/AH32,0) -> 0 | AN32: =IFERROR(AL32/AG32,0) -> 0 | AP32: 46170 | AV32: =SUM(AR32:AU32) -> 0 | AW32: =IFERROR(AV32/AR32,0) -> 0 | AX32: =IFERROR(AV32/AQ32,0) -> 0 | AZ32: 46201 | BF32: =SUM(BB32:BE32) -> 0 | BG32: =IFERROR(BF32/BB32,0) -> 0 | BH32: =IFERROR(BF32/BA32,0) -> 0 | BJ32: 46231 | BP32: =SUM(BL32:BO32) -> 0 | BQ32: =IFERROR(BP32/BL32,0) -> 0 | BR32: =IFERROR(BP32/BK32,0) -> 0 | BT32: 46262 | BZ32: =SUM(BV32:BY32) -> 0 | CA32: =IFERROR(BZ32/BV32,0) -> 0 | CB32: =IFERROR(BZ32/BU32,0) -> 0 | CD32: 46293 | CJ32: =SUM(CF32:CI32) -> 0 | CK32: =IFERROR(CJ32/CF32,0) -> 0 | CL32: =IFERROR(CJ32/CE32,0) -> 0 | CN32: 46323 | CT32: =SUM(CP32:CS32) -> 0 | CU32: =IFERROR(CT32/CP32,0) -> 0 | CV32: =IFERROR(CT32/CO32,0) -> 0 | CX32: 46354 | DD32: =SUM(CZ32:DC32) -> 0 | DE32: =IFERROR(DD32/CZ32,0) -> 0 | DF32: =IFERROR(DD32/CY32,0) -> 0 | DH32: 46384 | DN32: =SUM(DJ32:DM32) -> 0 | DO32: =IFERROR(DN32/DJ32,0) -> 0 | DP32: =IFERROR(DN32/DI32,0) -> 0
B33: 46051 | C33: 14 | D33: 9661 | E33: 1085 | F33: 353 | G33: 3127 | H33: =SUM(D33:G33) -> 14226 | I33: =IFERROR(H33/D33,0) -> 1.4725184 | J33: =IFERROR(H33/C33,0) -> 1016.1429 | V33: 46110 | AB33: =SUM(X33:AA33) -> 0 | AC33: =IFERROR(AB33/X33,0) -> 0 | AD33: =IFERROR(AB33/W33,0) -> 0 | AF33: 46141 | AL33: =SUM(AH33:AK33) -> 0 | AM33: =IFERROR(AL33/AH33,0) -> 0 | AN33: =IFERROR(AL33/AG33,0) -> 0 | AP33: 46171 | AV33: =SUM(AR33:AU33) -> 0 | AW33: =IFERROR(AV33/AR33,0) -> 0 | AX33: =IFERROR(AV33/AQ33,0) -> 0 | AZ33: 46202 | BF33: =SUM(BB33:BE33) -> 0 | BG33: =IFERROR(BF33/BB33,0) -> 0 | BH33: =IFERROR(BF33/BA33,0) -> 0 | BJ33: 46232 | BP33: =SUM(BL33:BO33) -> 0 | BQ33: =IFERROR(BP33/BL33,0) -> 0 | BR33: =IFERROR(BP33/BK33,0) -> 0 | BT33: 46263 | BZ33: =SUM(BV33:BY33) -> 0 | CA33: =IFERROR(BZ33/BV33,0) -> 0 | CB33: =IFERROR(BZ33/BU33,0) -> 0 | CD33: 46294 | CJ33: =SUM(CF33:CI33) -> 0 | CK33: =IFERROR(CJ33/CF33,0) -> 0 | CL33: =IFERROR(CJ33/CE33,0) -> 0 | CN33: 46324 | CT33: =SUM(CP33:CS33) -> 0 | CU33: =IFERROR(CT33/CP33,0) -> 0 | CV33: =IFERROR(CT33/CO33,0) -> 0 | CX33: 46355 | DD33: =SUM(CZ33:DC33) -> 0 | DE33: =IFERROR(DD33/CZ33,0) -> 0 | DF33: =IFERROR(DD33/CY33,0) -> 0 | DH33: 46385 | DN33: =SUM(DJ33:DM33) -> 0 | DO33: =IFERROR(DN33/DJ33,0) -> 0 | DP33: =IFERROR(DN33/DI33,0) -> 0
B34: 46052 | C34: 0 | D34: 0 | E34: 0 | F34: 0 | G34: 0 | H34: =SUM(D34:G34) -> 0 | I34: =IFERROR(H34/D34,0) -> 0 | J34: =IFERROR(H34/C34,0) -> 0 | V34: 46111 | AB34: =SUM(X34:AA34) -> 0 | AC34: =IFERROR(AB34/X34,0) -> 0 | AD34: =IFERROR(AB34/W34,0) -> 0 | AF34: 46142 | AL34: =SUM(AH34:AK34) -> 0 | AM34: =IFERROR(AL34/AH34,0) -> 0 | AN34: =IFERROR(AL34/AG34,0) -> 0 | AP34: 46172 | AV34: =SUM(AR34:AU34) -> 0 | AW34: =IFERROR(AV34/AR34,0) -> 0 | AX34: =IFERROR(AV34/AQ34,0) -> 0 | AZ34: 46203 | BF34: =SUM(BB34:BE34) -> 0 | BG34: =IFERROR(BF34/BB34,0) -> 0 | BH34: =IFERROR(BF34/BA34,0) -> 0 | BJ34: 46233 | BP34: =SUM(BL34:BO34) -> 0 | BQ34: =IFERROR(BP34/BL34,0) -> 0 | BR34: =IFERROR(BP34/BK34,0) -> 0 | BT34: 46264 | BZ34: =SUM(BV34:BY34) -> 0 | CA34: =IFERROR(BZ34/BV34,0) -> 0 | CB34: =IFERROR(BZ34/BU34,0) -> 0 | CD34: 46295 | CJ34: =SUM(CF34:CI34) -> 0 | CK34: =IFERROR(CJ34/CF34,0) -> 0 | CL34: =IFERROR(CJ34/CE34,0) -> 0 | CN34: 46325 | CT34: =SUM(CP34:CS34) -> 0 | CU34: =IFERROR(CT34/CP34,0) -> 0 | CV34: =IFERROR(CT34/CO34,0) -> 0 | CX34: 46356 | DD34: =SUM(CZ34:DC34) -> 0 | DE34: =IFERROR(DD34/CZ34,0) -> 0 | DF34: =IFERROR(DD34/CY34,0) -> 0 | DH34: 46386 | DN34: =SUM(DJ34:DM34) -> 0 | DO34: =IFERROR(DN34/DJ34,0) -> 0 | DP34: =IFERROR(DN34/DI34,0) -> 0
B35: 46053 | C35: 14 | D35: 11081 | E35: 1207 | F35: 414 | G35: 3842 | H35: =SUM(D35:G35) -> 16544 | I35: =IFERROR(H35/D35,0) -> 1.493006 | J35: =IFERROR(H35/C35,0) -> 1181.7143 | V35: 46112 | AB35: =SUM(X35:AA35) -> 0 | AC35: =IFERROR(AB35/X35,0) -> 0 | AD35: =IFERROR(AB35/W35,0) -> 0 | AP35: 46173 | AV35: =SUM(AR35:AU35) -> 0 | AW35: =IFERROR(AV35/AR35,0) -> 0 | AX35: =IFERROR(AV35/AQ35,0) -> 0 | BJ35: 46234 | BP35: =SUM(BL35:BO35) -> 0 | BQ35: =IFERROR(BP35/BL35,0) -> 0 | BR35: =IFERROR(BP35/BK35,0) -> 0 | BT35: 46265 | BZ35: =SUM(BV35:BY35) -> 0 | CA35: =IFERROR(BZ35/BV35,0) -> 0 | CB35: =IFERROR(BZ35/BU35,0) -> 0 | CN35: 46326 | CT35: =SUM(CP35:CS35) -> 0 | CU35: =IFERROR(CT35/CP35,0) -> 0 | CV35: =IFERROR(CT35/CO35,0) -> 0 | DH35: 46387 | DN35: =SUM(DJ35:DM35) -> 0 | DO35: =IFERROR(DN35/DJ35,0) -> 0 | DP35: =IFERROR(DN35/DI35,0) -> 0
